nohup: ignoring input
/venv/main/lib/python3.10/site-packages/torch/distributed/launch.py:178: FutureWarning: The module torch.distributed.launch is deprecated
and will be removed in future. Use torchrun.
Note that --use_env is set by default in torchrun.
If your script expects `--local_rank` argument to be set, please
change it to read from `os.environ['LOCAL_RANK']` instead. See 
https://pytorch.org/docs/stable/distributed.html#launch-utility for 
further instructions

  warnings.warn(
WARNING:torch.distributed.run:
*****************************************
Setting OMP_NUM_THREADS environment variable for each process to be 1 in default, to avoid your system being overloaded, please further tune the variable for optimal performance in your application as needed. 
*****************************************
Traceback (most recent call last):
  File "/workspace/thefinalrace/tools/train.py", line 104, in <module>
    main()
  File "/workspace/thefinalrace/tools/train.py", line 58, in main
    cfg = Config.fromfile(args.config)
  File "/venv/main/lib/python3.10/site-packages/mmengine/config/config.py", line 460, in fromfile
    lazy_import is None and not Config._is_lazy_import(filename):
  File "/venv/main/lib/python3.10/site-packages/mmengine/config/config.py", line 1662, in _is_lazy_import
    with open(filename, encoding='utf-8') as f:
FileNotFoundError: [Errno 2] No such file or directory: 'configs/segformer/RTX3090_segformer_mit-b3_8xb2-160k_rescuenet-512x512.py'
Traceback (most recent call last):
  File "/workspace/thefinalrace/tools/train.py", line 104, in <module>
    main()
  File "/workspace/thefinalrace/tools/train.py", line 58, in main
    cfg = Config.fromfile(args.config)
  File "/venv/main/lib/python3.10/site-packages/mmengine/config/config.py", line 460, in fromfile
    lazy_import is None and not Config._is_lazy_import(filename):
  File "/venv/main/lib/python3.10/site-packages/mmengine/config/config.py", line 1662, in _is_lazy_import
    with open(filename, encoding='utf-8') as f:
FileNotFoundError: [Errno 2] No such file or directory: 'configs/segformer/RTX3090_segformer_mit-b3_8xb2-160k_rescuenet-512x512.py'
Traceback (most recent call last):
  File "/workspace/thefinalrace/tools/train.py", line 104, in <module>
    main()
  File "/workspace/thefinalrace/tools/train.py", line 58, in main
    cfg = Config.fromfile(args.config)
  File "/venv/main/lib/python3.10/site-packages/mmengine/config/config.py", line 460, in fromfile
    lazy_import is None and not Config._is_lazy_import(filename):
  File "/venv/main/lib/python3.10/site-packages/mmengine/config/config.py", line 1662, in _is_lazy_import
    with open(filename, encoding='utf-8') as f:
FileNotFoundError: [Errno 2] No such file or directory: 'configs/segformer/RTX3090_segformer_mit-b3_8xb2-160k_rescuenet-512x512.py'
Traceback (most recent call last):
  File "/workspace/thefinalrace/tools/train.py", line 104, in <module>
    main()
  File "/workspace/thefinalrace/tools/train.py", line 58, in main
    cfg = Config.fromfile(args.config)
  File "/venv/main/lib/python3.10/site-packages/mmengine/config/config.py", line 460, in fromfile
    lazy_import is None and not Config._is_lazy_import(filename):
  File "/venv/main/lib/python3.10/site-packages/mmengine/config/config.py", line 1662, in _is_lazy_import
    with open(filename, encoding='utf-8') as f:
FileNotFoundError: [Errno 2] No such file or directory: 'configs/segformer/RTX3090_segformer_mit-b3_8xb2-160k_rescuenet-512x512.py'
ERROR:torch.distributed.elastic.multiprocessing.api:failed (exitcode: 1) local_rank: 0 (pid: 8360) of binary: /venv/main/bin/python
Traceback (most recent call last):
  File "/usr/lib/python3.10/runpy.py", line 196, in _run_module_as_main
    return _run_code(code, main_globals, None,
  File "/usr/lib/python3.10/runpy.py", line 86, in _run_code
    exec(code, run_globals)
  File "/venv/main/lib/python3.10/site-packages/torch/distributed/launch.py", line 193, in <module>
    main()
  File "/venv/main/lib/python3.10/site-packages/torch/distributed/launch.py", line 189, in main
    launch(args)
  File "/venv/main/lib/python3.10/site-packages/torch/distributed/launch.py", line 174, in launch
    run(args)
  File "/venv/main/lib/python3.10/site-packages/torch/distributed/run.py", line 752, in run
    elastic_launch(
  File "/venv/main/lib/python3.10/site-packages/torch/distributed/launcher/api.py", line 131, in __call__
    return launch_agent(self._config, self._entrypoint, list(args))
  File "/venv/main/lib/python3.10/site-packages/torch/distributed/launcher/api.py", line 245, in launch_agent
    raise ChildFailedError(
torch.distributed.elastic.multiprocessing.errors.ChildFailedError: 
============================================================
tools/train.py FAILED
------------------------------------------------------------
Failures:
[1]:
  time      : 2025-03-31_10:58:03
  host      : b64c28ecd82f
  rank      : 1 (local_rank: 1)
  exitcode  : 1 (pid: 8361)
  error_file: <N/A>
  traceback : To enable traceback see: https://pytorch.org/docs/stable/elastic/errors.html
[2]:
  time      : 2025-03-31_10:58:03
  host      : b64c28ecd82f
  rank      : 2 (local_rank: 2)
  exitcode  : 1 (pid: 8362)
  error_file: <N/A>
  traceback : To enable traceback see: https://pytorch.org/docs/stable/elastic/errors.html
[3]:
  time      : 2025-03-31_10:58:03
  host      : b64c28ecd82f
  rank      : 3 (local_rank: 3)
  exitcode  : 1 (pid: 8363)
  error_file: <N/A>
  traceback : To enable traceback see: https://pytorch.org/docs/stable/elastic/errors.html
------------------------------------------------------------
Root Cause (first observed failure):
[0]:
  time      : 2025-03-31_10:58:03
  host      : b64c28ecd82f
  rank      : 0 (local_rank: 0)
  exitcode  : 1 (pid: 8360)
  error_file: <N/A>
  traceback : To enable traceback see: https://pytorch.org/docs/stable/elastic/errors.html
============================================================
